Workbook

Sheet COVER
A1: PROJECT LUMINA
A5: AURA Consumer Sciences Ltd | IPO Valuation | FinOrbits IB Championship Season 1
A8: SUBMISSION DETAILS
A9: Participant Name | C9: Muneer Ahmad
A11: College / Firm | C11: Aligarh Muslim University Malappuram Centre
A13: Submission Date | C13: 22/04/2026
A17: COLOR LEGEND & USAGE GUIDE
A18: Blue bold text | C18: Input cells — type your assumptions here
A19: Black text | C19: Formula cells — calculated automatically, do not type
A20: Green text | C20: Cross-tab links — pulling from another sheet
A21: Light blue bg | C21: Assumption input cells — fill these in
A23: INSTRUCTIONS — READ BEFORE BUILDING
A24: Step 1 | Read the CIM (Project Lumina) and the FinOrbits IB Analyst Handbook completely.
A25: Step 2 | Go to PROJECTIONS tab. Enter your revenue, margin, and working capital assumptions in blue cells.
A26: Step 3 | Go to DCF tab. Enter all WACC inputs — research your own risk-free rate, ERP, beta, and cost of debt. All FCF rows are pre-structured.
A27: Step 4 | Go to COMPARABLES tab. Select your applied multiple and enter your premium/discount commentary.
A28: Step 5 | Complete SUMMARY tab. Fill valuation ranges, weights, and your final IPO recommendation.
A29: RULE: Never hardcode a number inside a formula cell. Blue = your input. Black = formula calculates.
A30: RULE: Every assumption must be justified in your Investment Memo submission.
A32: CONFIDENTIAL | Project Lumina | FinOrbits IB Championship S1 | finorbits.com

Sheet HISTORICAL
A1: HISTORICAL FINANCIALS — AURA CONSUMER SCIENCES LTD
A5: READ-ONLY | Sourced from AURA audited financials. Do not edit.
A7: INCOME STATEMENT (₹ Crore)
A8: ₹ Crore | B8: FY2022A | C8: FY2023A | D8: FY2024A
A9: Revenue | B9: 112 | C9: 163 | D9: 224
A10: COGS | B10: -67.2 | C10: -95.4 | D10: -126
A11: Gross Profit | B11: =B9+B10 -> 44.8 | C11: =C9+C10 -> 67.6 | D11: =D9+D10 -> 98
A12: Gross Margin % | B12: =B11/B9 -> 0.4 | C12: =C11/C9 -> 0.41472393 | D12: =D11/D9 -> 0.4375
A13: EBITDA | B13: 8.4 | C13: 16.3 | D13: 26.9
A14: EBITDA Margin % | B14: =B13/B9 -> 0.075 | C14: =C13/C9 -> 0.1 | D14: =D13/D9 -> 0.12008929
A15: D&A | B15: -1.2 | C15: -1.7 | D15: -2.6
A16: EBIT | B16: 7.2 | C16: 14.6 | D16: 24.3
A17: Other Income | B17: 0.3 | C17: 0.4 | D17: 0.5
A18: Interest Expense | B18: -1.8 | C18: -2.5 | D18: -3.2
A19: PBT | B19: 5.7 | C19: 12.5 | D19: 21.6
A20: Tax (25%) | B20: -3.6 | C20: -6 | D20: -8.2
A21: PAT | B21: 2.1 | C21: 6.5 | D21: 13.4
A22: PAT Margin % | B22: =B21/B9 -> 0.01875 | C22: =C21/C9 -> 0.039877301 | D22: =D21/D9 -> 0.059821429
A25: BALANCE SHEET (₹ Crore)
A26: ₹ Crore | B26: FY2022A | C26: FY2023A | D26: FY2024A
A27: ASSETS
A28: Fixed Assets (Net) | B28: 65 | C28: 89 | D28: 112
A29: Inventories | B29: 18 | C29: 24 | D29: 31
A30: Trade Receivables | B30: 12 | C30: 16.5 | D30: 22
A31: Cash & Equivalents | B31: 14 | C31: 21 | D31: 28
A32: Other Current Assets | B32: 5 | C32: 6.5 | D32: 5
A33: TOTAL ASSETS | B33: =B28+B29+B30+B31+B32 -> 114 | C33: =C28+C29+C30+C31+C32 -> 157 | D33: =D28+D29+D30+D31+D32 -> 198
A34: LIABILITIES & EQUITY
A35: Long-Term Debt | B35: 22 | C35: 31 | D35: 42
A36: Trade Payables | B36: 15 | C36: 19 | D36: 26
A37: Other Liabilities | B37: 8 | C37: 10 | D37: 18
A38: Total Equity | B38: 69 | C38: 97 | D38: 112
A39: TOTAL L & E | B39: =B35+B36+B37+B38 -> 114 | C39: =C35+C36+C37+C38 -> 157 | D39: =D35+D36+D37+D38 -> 198
A42: KEY FINANCIAL RATIOS
A43: Ratio | B43: FY2022A | C43: FY2023A | D43: FY2024A
A44: Revenue Growth YoY | B44: - | C44: =C9/B9-1 -> 0.45535714 | D44: =D9/C9-1 -> 0.37423313
A45: EBITDA Margin | B45: =B13/B9 -> 0.075 | C45: =C13/C9 -> 0.1 | D45: =D13/D9 -> 0.12008929
A46: Debt/Equity Ratio | B46: =B35/B38 -> 0.31884058 | C46: =C35/C38 -> 0.31958763 | D46: =D35/D38 -> 0.375
A47: Interest Coverage | B47: =B16/ABS(B18) -> 4 | C47: =C16/ABS(C18) -> 5.84 | D47: =D16/ABS(D18) -> 7.59375
A48: Return on Equity | B48: =B21/B38 -> 0.030434783 | C48: =C21/C38 -> 0.067010309 | D48: =D21/D38 -> 0.11964286
...

Sheet ASSUMPTIONS
B1: VALUES & BASIS OF ASSUMPTION — PROJECT LUMINA | AURA Consumer Sciences Ltd
B2: Complete this sheet before submitting your model. Every blue assumption in PROJECTIONS and DCF VALUATION must have a documented value (col D) and written justification (col E). Graders will evaluate this sheet independently.
B3: Assumption | C3: Your Value (Blue = Input) | D3: Basis of Assumption — Write Clearly (This is Graded)
B4: SECTION 1 — INCOME STATEMENT ASSUMPTIONS (PROJECTIONS sheet)
B5: Revenue Growth Rate % | C5: 0.41 | D5: Projected using a growth-dacay model; starting at the 2-year historical average (41%) and Decay factor 10% to reflect market saturation and increased competition.
B6: Gross Margin % | C6: =HISTORICAL!D12 -> 0.4375 | D6: Projected to expand by 150 basis points annually due to economies of scale in procurement and improved production efficiency as volume scales.
B7: EBITDA Margin % | C7: 0.135 | D7: Projected to expand by 1.5% due to operating leverage; as revenue scales, fixed indirect costs are spread across a larger base , improving overall profitability.
B8: D&A as % of Revenue | C8: 0.012 | D8: D&A is assumed at ~1.2% of revenue in line with historical trends , reflecting a relatively asse-light business model with capex growing proportionally with revenue.
B9: Tax Rate % | C9: 0.25 | D9: Maintained at a constant 25%, reflecting the prevailing statutory corporate tax rate for domestic companies in India. The forecast assumes no major legislative changes or eligibility for new tax holidays during the projection period.
B10: Capex as % of Revenue | C10: 9%/8%/7%/6.3/5.5 | D10: Capex as a % of revenue is projected to follow a declining trend from 9% to 5.5%, following the historical trajectory ( which decreased from 15.8% to 11.4%). This reflects a transition from an aggressive initial infrastructure build out phase to a steady state maintainance and replacement cycle as the business matures.
B11: SECTION 2 — WORKING CAPITAL ASSUMPTIONS (PROJECTIONS sheet)
B12: Debtor Days (Receivables) | C12: 36 Days | D12: Maintained at a 36 Days as per CIM guidance, reflecting the high percentage of D2C and quick-commerce revenue (68%) which typically involves shorter collection cycles than traditional trade.
B13: Creditor Days (Payables) | C13: 75 Days | D13: Held constant at the derived historical level of 75 days, assuming the company maintains its established credit terms with third party contract manufactures as it scales.
B14: Inventory Days | C14: 50 Days | D14: Projected at 50 days in line with CIM risk disclosures, reflecting the balance between managing perishable cold pressed juices (3-5 day shelf life) and maintaining safety stock for non perishable supplements.
B15: SECTION 3 — INTEREST EXPENSE (PROJECTIONS sheet)
B16: Interest Expense FY2025E onward | C16: 0.004 | D16: Interest Expense is projected to follow a declining trend ( by 0.05% from previous year's expense ) as a percentage of revenue, reflecting the company's improved credit profile and the strategic allocation of Rs.30 cr from the IPO fresh issue proceeds to repay existing long term debt, as specified in the transaction summary.
B17: SECTION 4 — WACC ASSUMPTIONS (DCF VALUATION sheet)
B18: Risk-Free Rate (Rf) | C18: 0.068 | D18: Source: RBI/ NSE India 10 year government Bond Yield is hovering around 6.89% - 6.91%. As of mid april 2026
B19: Equity Risk Premium (ERP) | C19: 0.07 | D19: As of January 2026, the estimated Equity Risk Premium in India is recommended at approximately 7.0%, with a suggested range between 6.5% and 7.5%, according to Incwert's 2026 India ERP study.
B20: Beta (Levered) | C20: 0.75 | D20: Peer Unlevered beta: Honasa 0.34, Tata Consumer 0.36, Marico 0.15, Emami 0.12, Bikaji 0.23 (5 years monthly), Peer Median unlevered Beta = 0.22, Re-levered at Aura's post-IPO target Capital structure. Aura Levered Beta = Median unlevered beta *[1+(1-Tax Rate )*(D/E)], Aura levered beta = 0.22*[1+(0.75*0.008)] = 0.23 Adjusted upward to 0.75 for AURA growth risk premium (
B21: Cost of Debt (pre-tax Kd) | C21: 0.076 | D21: Pre-tax cost of debt is estimated at 7.6%, derived from the FY2024 historical interest expense and long term debt balance.
B22: Debt Weight D/V | C22: 0.1 | D22: Post IPO Equity = ₹ 860 Cr , pre- IPO ₹660 Cr based on peer multiple and ₹66/ share mid point. Fresh issue ₹200 Cr. The D/V ratio is based on the target post IPO capital structure. Whilethe D/V is 1.38% , a 10% weight is assumed for WACC calcualation.
B23: SECTION 5 — TERMINAL VALUE (DCF VALUATION sheet)
B24: Terminal Growth Rate (g) | C24: 0.05 | D24: Terminal Growth Rate is set at 5.0%. This is consistent with the long run sustainable growth expectation for the Indian D2C wellness and nutrition sector. It remains conservatively below india's projected nominal GDP growth rate.
B25: SECTION 6 — EV-TO-EQUITY BRIDGE (DCF VALUATION sheet)
B26: Net Debt | C26: -16 | D26: Derive from FY2024 Balance Sheet: Long-Term Debt (42) minus Cash & Equivalents (28) = 14 (pre-IPO). Post-IPO: Rs. 30 Cr of fresh issue proceeds repay debt, so Long-Term Debt falls to 12 and Net Debt = 12 − 28 = -16
B27: Shares Outstanding | C27: 10 Cr ( Pre-IPO) | D27: Pre-filled per CIM Transaction Summary: 10 Crore pre-IPO shares outstanding. Fresh issue will create additional dilution — post-IPO shares depend on IPO price. At ₹66 mid-band price: Fresh issue ₹200 Cr / ₹66 = 3.03 Cr new shares. Total post-IPO = 13.03 Cr. This model uses pre-IPO 10 Cr shares per template instruction.
B28: SECTION 7 — COMPARABLES: APPLIED MULTIPLES (COMPARABLES sheet)
B29: Peer Company Selection Rationale | C29: Honasa Consumer (Mamaearth) | Marico Ltd | Emami Ltd | Bikaji Foods | Tata Consumer Products | D29: 1. Honasa (Mamaearth): Closest D2C brand analog — listed FY24, premium D2C consumer brand, high-growth, digital-first. Direct structural comparator for AURA. 2. Marico: India FMCG premium health/wellness (Saffola, Parachute). Similar consumer segment — health-conscious urban. Provides EBITDA/multiple benchmark at scale. 3. Emami: Ayurvedic wellness & personal care. Premium Indian consumer health brand with strong margins. Comparable on product positioning and consumer archetype. 4. Bikaji Foods: Premium branded packaged food (snacks). Revenue scale comparable to AURA near-term projection range. Similar quick-commerce distribution overlap. 5. Tata Consumer Products: Large-cap FMCG health & wellness (Tata Sampann, Himalayan). Provides upper-bound multiple reference. Adjusted down for AURA scale gap. Data source: NSE/BSE market data, company annual reports FY2025. All figures in INR Crore.
B30: EV/Revenue Multiple Applied | C30: 5.0x | D30: The applied EV/Revenue multiple of 5x is based on the premium assigned to high growth, digital first D2C brands in India.
B31: EV/EBITDA Multiple Applied | C31: 40x | D31: An EV/EBITDA multiple of 40x is utilised as the primary valuation benchmark. This aligns with the peer median for listed FMCG and personal care leaders ( eg. Tata consumer , Marico ) who exhibit similar operational stability.
B32: P/E Multiple Applied | C32: 52x | D32: The Price to Earnings(P/E) multiple of 52x reflects the market's willingness to pay a premium for consistent earnings growth in the wellness sector. This assumption is consistent with the long term historical trading averages of diversified consumer goods companies in India.
B34: CONFIDENTIAL | Project Lumina | FinOrbits IB Simulation Season 1 | finorbits.com
D37: 9

Sheet PROJECTIONS
A1: PROJECTIONS — FY2025E | FY2026E | FY2027E | FY2028E | FY2029E
A5: Enter assumptions in BLUE cells only. Every assumption must be justified in your Investment Memo. All projection years (FY2025E–FY2029E) are fully analyst-driven — no figures are pre-given. Refer to the CIM Analyst Guidance for reference points.
A7: SECTION 1 — KEY ASSUMPTIONS (Blue = your inputs)
A8: Assumption | B8: FY2025E | C8: FY2026E | D8: FY2027E | E8: FY2028E | F8: FY2029E | G8: Basis of assumption
A9: Revenue Growth Rate % | B9: =ASSUMPTIONS!C5 -> 0.41 | C9: 0.369 | D9: 0.332 | E9: 0.299 | F9: 0.269 | G9: Projected using a growth-dacay model
A10: Gross Margin % | B10: 0.453 | C10: 0.468 | D10: 0.483 | E10: 0.498 | F10: 0.513 | G10: Projected to expand by 150 basis points annually
A11: EBITDA Margin % | B11: =ASSUMPTIONS!C7 -> 0.135 | C11: 0.15 | D11: 0.165 | E11: 0.18 | F11: 0.195 | G11: Projected to expand by 1.5% due to operating leverage
A12: D&A as % of Revenue | B12: =ASSUMPTIONS!C8 -> 0.012 | C12: 0.0125 | D12: 0.013 | E12: 0.013 | F12: 0.0135 | G12: D&A is assumed at ~1.2% of revenue in line with historical trends
A13: Tax Rate % | B13: =ASSUMPTIONS!C9 -> 0.25 | C13: 0.25 | D13: 0.25 | E13: 0.25 | F13: 0.25 | G13: Maintained at a constant 25%
A14: Capex as % of Revenue | B14: 0.09 | C14: 0.08 | D14: 0.07 | E14: 0.063 | F14: 0.055 | G14: Capex as a % of revenue is projected to follow a declining trend from 9% to 5.5%
A15: Debtor Days | B15: 36 | C15: 36 | D15: 36 | E15: 36 | F15: 36 | G15: Maintained at a 36 Days as per CIM guidance
A16: Creditor Days | B16: 75 | C16: 75 | D16: 75 | E16: 75 | F16: 75 | G16: Held constant at the derived historical level of 75 days
A17: Inventory Days | B17: 50 | C17: 50 | D17: 50 | E17: 50 | F17: 50 | G17: Projected at 50 days in line with CIM risk disclosures
A19: SECTION 2 — PROJECTED INCOME STATEMENT (₹ Crore)
A20: ₹ Crore | B20: FY2022A | C20: FY2023A | D20: FY2024A | E20: FY2025E | F20: FY2026E | G20: FY2027E | H20: FY2028E | I20: FY2029E
A21: Revenue | B21: 112 | C21: 163 | D21: 224 | E21: =D21*(1+B9) -> 315.84 | F21: =E21*(1+C9) -> 432.38496 | G21: =F21*(1+D9) -> 575.93677 | H21: =G21*(1+E9) -> 748.14186 | I21: =H21*(1+F9) -> 949.39202
A22: COGS | B22: -67.2 | C22: -95.4 | D22: -126 | E22: =-(E21*(1-B10)) -> -172.76448 | F22: =-(F21*(1-C10)) -> -230.0288 | G22: =-(G21*(1-D10)) -> -297.75931 | H22: =-(H21*(1-E10)) -> -375.56721 | I22: =-(I21*(1-F10)) -> -462.35391
A23: Gross Profit | B23: 44.8 | C23: 67.6 | D23: 98 | E23: =E21+E22 -> 143.07552 | F23: =F21+F22 -> 202.35616 | G23: =G21+G22 -> 278.17746 | H23: =H21+H22 -> 372.57465 | I23: =I21+I22 -> 487.03811
A24: Gross Margin % | B24: 0.4 | C24: 0.415 | D24: 0.438 | E24: =E23/E21 -> 0.453 | F24: =F23/F21 -> 0.468 | G24: =G23/G21 -> 0.483 | H24: =H23/H21 -> 0.498 | I24: =I23/I21 -> 0.513
A25: EBITDA | B25: 8.4 | C25: 16.3 | D25: 26.9 | E25: =E21*E26 -> 42.6384 | F25: =F21*F26 -> 64.857744 | G25: =G21*G26 -> 95.029567 | H25: =H21*H26 -> 134.66553 | I25: =I21*I26 -> 185.13144
A26: EBITDA Margin % | B26: 0.075 | C26: 0.1 | D26: 0.12 | E26: =ASSUMPTIONS!C7 -> 0.135 | F26: =E26+1.5% -> 0.15 | G26: =F26+1.5% -> 0.165 | H26: =G26+1.5% -> 0.18 | I26: =H26+1.5% -> 0.195
A27: D&A | B27: -1.2 | C27: -1.7 | D27: -2.6 | E27: =-(E21*B12) -> -3.79008 | F27: =-(F21*C12) -> -5.404812 | G27: =-(G21*D12) -> -7.487178 | H27: =-(H21*E12) -> -9.7258442 | I27: =-(I21*F12) -> -12.816792
A28: EBIT | B28: 7.2 | C28: 14.6 | D28: 24.3 | E28: =E25+E27 -> 38.84832 | F28: =F25+F27 -> 59.452932 | G28: =G25+G27 -> 87.542389 | H28: =H25+H27 -> 124.93969 | I28: =I25+I27 -> 172.31465
A29: Other income | B29: 0.3 | C29: 0.4 | D29: 0.5 | E29: =D29+0.1 -> 0.6 | F29: =E29+0.1 -> 0.7 | G29: =F29+0.1 -> 0.8 | H29: =G29+0.1 -> 0.9 | I29: =H29+0.1 -> 1
A30: Interest Expense | B30: -1.8 | C30: -2.5 | D30: -3.2 | E30: =-(E21*ASSUMPTIONS!C16) -> -1.26336 | F30: =-(F21*0.35%) -> -1.5133474 | G30: =-(G21*0.3%) -> -1.7278103 | H30: =-(H21*0.25%) -> -1.8703546 | I30: =-(I21*0.2%) -> -1.898784
A31: PBT | B31: 5.7 | C31: 12.5 | D31: 21.6 | E31: =SUM(E28:E30) -> 38.18496 | F31: =SUM(F28:F30) -> 58.639585 | G31: =SUM(G28:G30) -> 86.614578 | H31: =SUM(H28:H30) -> 123.96934 | I31: =SUM(I28:I30) -> 171.41587
A32: Tax | B32: -3.6 | C32: -6 | D32: -8.2 | E32: =-(E31*25%) -> -9.54624 | F32: =-(F31*25%) -> -14.659896 | G32: =-(G31*25%) -> -21.653645 | H32: =-(H31*25%) -> -30.992334 | I32: =-(I31*25%) -> -42.853967
A33: PAT | B33: 2.1 | C33: 6.5 | D33: 13.4 | E33: =E31+E32 -> 28.63872 | F33: =F31+F32 -> 43.979688 | G33: =G31+G32 -> 64.960934 | H33: =H31+H32 -> 92.977002 | I33: =I31+I32 -> 128.5619
A34: PAT Margin % | B34: =B33/B21 -> 0.01875 | C34: =C33/C21 -> 0.039877301 | D34: =D33/D21 -> 0.059821429 | E34: =E33/E21 -> 0.090674772 | F34: =F33/F21 -> 0.1017142 | G34: =G33/G21 -> 0.11279178 | H34: =H33/H21 -> 0.12427724 | I34: =I33/I21 -> 0.13541498
A36: SECTION 3 — WORKING CAPITAL SCHEDULE (₹ Crore)
A37: ₹ Crore | B37: FY2022A | C37: FY2023A | D37: FY2024A | E37: FY2025E | F37: FY2026E | G37: FY2027E | H37: FY2028E | I37: FY2029E
A38: Inventories = Revenue × Inventory Days / 365 | B38: 18 | C38: 24 | D38: 31 | E38: =E21*B17/365 -> 43.265753 | F38: =F21*C17/365 -> 59.230816 | G38: =G21*D17/365 -> 78.895447 | H38: =H21*E17/365 -> 102.48519 | I38: =I21*F17/365 -> 130.0537 | J38: Formula: = Revenue x Inv Days / 365
A39: Trade Receivables = Revenue × Debtor Days / 365 | B39: 12 | C39: 16.5 | D39: 22 | E39: =E21*B15/365 -> 31.151342 | F39: =F21*C15/365 -> 42.646188 | G39: =G21*D15/365 -> 56.804722 | H39: =H21*E15/365 -> 73.789334 | I39: =I21*F15/365 -> 93.638665 | J39: Formula: = Revenue x Debtor Days / 365
A40: Trade Payables = COGS × Creditor Days / 365 | B40: 15 | C40: 19 | D40: 26 | E40: =ABS(E22*B16/365) -> 35.499551 | F40: =ABS(F22*C16/365) -> 47.266192 | G40: =ABS(G22*D16/365) -> 61.18342 | H40: =ABS(H22*E16/365) -> 77.171345 | I40: =ABS(I22*F16/365) -> 95.004229 | J40: Formula: = ABS(COGS) x Creditor Days / 365
A41: Net Working Capital = Inventories + Receivables − Payables | B41: 15 | C41: 21.5 | D41: 27 | E41: =E38+E39-E40 -> 38.917545 | F41: =F38+F39-F40 -> 54.610813 | G41: =G38+G39-G40 -> 74.51675 | H41: =H38+H39-H40 -> 99.103175 | I41: =I38+I39-I40 -> 128.68814 | J41: Inventories + Receivables minus Payables
A42: Change in WC = Net WC(t) − Net WC(t−1) ← link this row to DCF | B42: — | C42: 6.5 | D42: 5.5 | E42: 11.885096 | F42: 11.885096 | G42: 11.885096 | H42: 11.885096 | I42: 11.885096 | J42: Positive delta WC = cash outflow. Deduct in FCF.
A44: SECTION 4 — INTEREST EXPENSE ASSUMPTION
A45: Crore | B45: FY2022A | C45: FY2023A | D45: FY2024A | E45: FY2025E | F45: FY2026E | G45: FY2027E | H45: FY2028E | I45: FY2029E
A46: Interest Expense | B46: -1.8 | C46: -2.5 | D46: -3.2 | E46: =E30 -> -1.26336 | F46: =F30 -> -1.5133474 | G46: =G30 -> -1.7278103 | H46: =H30 -> -1.8703546 | I46: =I30 -> -1.898784
A49: CONFIDENTIAL | Project Lumina | FinOrbits IB Championship S1

Sheet DCF VALUATION
A1: DCF VALUATION — DISCOUNTED CASH FLOW ANALYSIS
A6: SECTION 1 — WACC CALCULATION
A7: Component | B7: Value | C7: Notes
A8: Risk-Free Rate (10-yr G-Sec) | B8: =ASSUMPTIONS!C18 -> 0.068
A9: Equity Risk Premium (ERP) | B9: =ASSUMPTIONS!C19 -> 0.07
A10: Beta (Levered) | B10: =ASSUMPTIONS!C20 -> 0.75
A11: Cost of Equity (CAPM) | B11: =B8+(B10*B9) -> 0.1205 | C11: = Rf + Beta x ERP. Auto-calculated.
A12: Cost of Debt (pre-tax) | B12: =ASSUMPTIONS!C21 -> 0.076
A13: Tax Rate | B13: =ASSUMPTIONS!C9 -> 0.25
A14: After-tax Cost of Debt | B14: =B12*(1-B13) -> 0.057 | C14: = Kd x (1-t). Auto-calculated.
A15: Debt Weight (D/V) | B15: =ASSUMPTIONS!C22 -> 0.1 | C15: Market value of debt / (Debt+Equity). Use FY24 BS.
A16: Equity Weight (E/V) | B16: =1-B15 -> 0.9
A17: WACC | B17: =B11*B16+B14*B15 -> 0.11415 | C17: = Ke x (E/V) + Kd(1-t) x (D/V). Your discount rate.
A19: SECTION 2 — FREE CASH FLOW (FCFF) | FY2025E-FY2029E
A20: ₹ Crore | B20: FY2025E | C20: FY2026E | D20: FY2027E | E20: FY2028E | F20: FY2029E
A21: EBIT (from your Projections tab) | B21: =PROJECTIONS!E28 -> 38.84832 | C21: =PROJECTIONS!F28 -> 59.452932 | D21: =PROJECTIONS!G28 -> 87.542389 | E21: =PROJECTIONS!H28 -> 124.93969 | F21: =PROJECTIONS!I28 -> 172.31465
A22: (-) Tax on EBIT = EBIT x Tax Rate | B22: =B21*$B$13 -> 9.71208 | C22: =C21*$B$13 -> 14.863233 | D22: =D21*$B$13 -> 21.885597 | E22: =E21*$B$13 -> 31.234923 | F22: =F21*$B$13 -> 43.078663
A23: NOPAT = EBIT x (1 - Tax Rate) | B23: =B21*(1-$B$13) -> 29.13624 | C23: =C21*(1-$B$13) -> 44.589699 | D23: =D21*(1-$B$13) -> 65.656791 | E23: =E21*(1-$B$13) -> 93.704768 | F23: =F21*(1-$B$13) -> 129.23599
A24: (+) D&A (add back) | B24: =-PROJECTIONS!E27 -> 3.79008 | C24: =-PROJECTIONS!F27 -> 5.404812 | D24: =-PROJECTIONS!G27 -> 7.487178 | E24: =-PROJECTIONS!H27 -> 9.7258442 | F24: =-PROJECTIONS!I27 -> 12.816792
A25: (-) Capex (cash outflow) | B25: =-PROJECTIONS!E21*PROJECTIONS!B14 -> -28.4256 | C25: =-PROJECTIONS!F21*PROJECTIONS!C14 -> -34.590797 | D25: =-PROJECTIONS!G21*PROJECTIONS!D14 -> -40.315574 | E25: =-PROJECTIONS!H21*PROJECTIONS!E14 -> -47.132937 | F25: =-PROJECTIONS!I21*PROJECTIONS!F14 -> -52.216561
A26: (-) Change in Working Capital | B26: =-PROJECTIONS!E42 -> -11.885096 | C26: =-PROJECTIONS!F42 -> -11.885096 | D26: =-PROJECTIONS!G42 -> -11.885096 | E26: =-PROJECTIONS!H42 -> -11.885096 | F26: =-PROJECTIONS!I42 -> -11.885096
A27: FREE CASH FLOW TO FIRM (FCFF) | B27: =B23+B24+B25+B26 -> -7.3843759 | C27: =C23+C24+C25+C26 -> 3.5186183 | D27: =D23+D24+D25+D26 -> 20.9433 | E27: =E23+E24+E25+E26 -> 44.412579 | F27: =F23+F24+F25+F26 -> 77.951124
A28: PV Factor = 1 / (1+WACC)^n | B28: =1/(1+$B$17)^1 -> 0.89754521 | C28: =1/(1+$B$17)^2 -> 0.80558741 | D28: =1/(1+$B$17)^3 -> 0.72305112 | E28: =1/(1+$B$17)^4 -> 0.64897108 | F28: =1/(1+$B$17)^5 -> 0.58248088
A29: Present Value of FCF | B29: =B27*B28 -> -6.6278112 | C29: =C27*C28 -> 2.8345546 | D29: =D27*D28 -> 15.143076 | E29: =E27*E28 -> 28.822479 | F29: =F27*F28 -> 45.40504
A31: GUIDANCE: Link EBIT and D&A from your PROJECTIONS Income Statement. Capex = Revenue × Capex%. Change in Working Capital from your PROJECTIONS Working Capital Schedule. Note: FCF uses FCFF method — interest expense is excluded from the FCF build (it sits in the IS only).
A33: SECTION 3 — TERMINAL VALUE
A34: Item | B34: Value | C34: Notes
A35: Terminal Growth Rate (g) | B35: =ASSUMPTIONS!C24 -> 0.05 | C35: India nominal long-run GDP growth. Typically 5-7%. Must be < WACC.
A36: Terminal Year FCFF (FY2029E) | B36: =F27 -> 77.951124 | C36: Link from FCF row above (FCFF FY2029E).
A37: Terminal Value = FCFF x (1+g) / (WACC-g) | B37: =B36*(1+B35)/(B17-B35) -> 1275.8952 | C37: Gordon Growth Model: TV = Terminal FCFF × (1+g) / (WACC - g). Use your WACC and terminal growth inputs above.
A38: Discount Factor (Year 5) | B38: =1/(1+B17)^5 -> 0.58248088 | C38: = 1/(1+WACC)^5
A39: PV of Terminal Value | B39: =B37*B38 -> 743.18459 | C39: Terminal Value × Discount Factor. Should be ~60-75% of total EV.
B40: =B41 -> 0
A42: SECTION 4 — EV TO EQUITY VALUE BRIDGE
A43: Item | B43: ₹ Crore | C43: Notes
A44: Sum of PV of FCFs (Years 1-5) | B44: =SUM(B29:F29) -> 85.577339 | C44: Sum of PV FCF from Section 2 above
A45: (+) PV of Terminal Value | B45: =B39 -> 743.18459 | C45: Link from the PV of Terminal Value you calculated in Section 3 above.
A46: Enterprise Value (EV) | B46: =B45+B44 -> 828.76193 | C46: = Sum of above two rows
A47: (-) Net Debt | B47: =(HISTORICAL!D35-HISTORICAL!D31)-30 -> -16 | C47: Derive from FY2024 Balance Sheet (Long-Term Debt minus Cash). Then adjust for ₹30 Cr debt repayment from IPO proceeds (see Transaction Summary). Show clearly whether you are using pre-IPO or post-IPO net debt, and justify.
A48: Equity Value | B48: =B46-B47 -> 844.76193 | C48: = EV minus Net Debt
...

Sheet COMPARABLES
A1: TRADING COMPARABLES — PEER GROUP ANALYSIS
A6: Company (Research & Enter Your Own Peers) | B6: Mkt Cap (₹cr) | C6: EV (₹cr) | D6: Revenue (₹cr) | E6: EBITDA (₹cr) | F6: EV/Revenue | G6: EV/EBITDA | H6: P/E | I6: Rev Growth % | J6: EBITDA Margin %
A7: Honasa Consumer Ltd | B7: ₹ 11,235 | C7: 11148 | D7: 2220 | E7: 204 | F7: =C7/D7 -> 5.0216216 | G7: =C7/E7 -> 54.647059 | H7: 72.7 | I7: 0.173 | J7: =E7/D7 -> 0.091891892
A8: Emami Ltd | B8: ₹ 19,734 | C8: 19578 | D8: 3817 | E8: 895 | F8: =C8/D8 -> 5.129159 | G8: =C8/E8 -> 21.87486 | H8: 24.6 | I8: 0.0214 | J8: =E8/D8 -> 0.23447734
A9: Tata Consumers | B9: ₹ 1,10,158 | C9: 110994 | D9: 17618 | E9: 2599 | F9: =C9/D9 -> 6.3000341 | G9: =C9/E9 -> 42.706426 | H9: 76 | I9: 0.149 | J9: =E9/D9 -> 0.14751958
A10: Marico Ltd | B10: ₹ 98,309 | C10: 98451 | D10: 10831 | E10: 2210 | F10: =C10/D10 -> 9.0897424 | G10: =C10/E10 -> 44.547964 | H10: 57.4 | I10: 0.253 | J10: =E10/D10 -> 0.20404395
A11: Bikaji l Ltd | B11: ₹ 16,550 | C11: 16574 | D11: 2622 | E11: 322 | F11: =C11/D11 -> 6.3211289 | G11: =C11/E11 -> 51.47205 | H11: 66.3 | I11: 0.0998 | J11: =E11/D11 -> 0.12280702
A13: PEER STATISTICS — Auto-calculated once you enter peer data above (Median = base case | Lower Q = bear | Upper Q = bull)
A14: Metric | C14: Peer Median | D14: Peer Mean | E14: Lower Quartile | F14: Upper Quartile
A15: EV/Revenue | C15: =MEDIAN(F7:F11) -> 6.3000341 | D15: =AVERAGE(F7:F11) -> 6.3723372 | E15: =QUARTILE(F7:F11,1) -> 5.129159 | F15: =QUARTILE(F7:F11,3) -> 6.3211289
A16: EV/EBITDA | C16: =MEDIAN(G7:G11) -> 44.547964 | D16: =AVERAGE(G7:G11) -> 43.049672 | E16: =QUARTILE(G7:G11,1) -> 42.706426 | F16: =QUARTILE(G7:G11,3) -> 51.47205
A17: P/E | C17: =MEDIAN(H7:H11) -> 66.3 | D17: =AVERAGE(H7:H11) -> 59.4 | E17: =QUARTILE(H7:H11,1) -> 57.4 | F17: =QUARTILE(H7:H11,3) -> 72.7
A18: Revenue Growth | C18: =MEDIAN(I7:I11) -> 0.149 | D18: =AVERAGE(I7:I11) -> 0.13924 | E18: =QUARTILE(I7:I11,1) -> 0.0998 | F18: =QUARTILE(I7:I11,3) -> 0.173
A19: EBITDA Margin | C19: =MEDIAN(J7:J11) -> 0.14751958 | D19: =AVERAGE(J7:J11) -> 0.16014796 | E19: =QUARTILE(J7:J11,1) -> 0.12280702 | F19: =QUARTILE(J7:J11,3) -> 0.20404395
A20: Peer Selection Rationale (explain why each company is a relevant comparable for AURA — sector, growth profile, business model similarity)
A22: AURA IMPLIED VALUATION — Enter your projected figures (blue cells)
A23: AURA Metric | B23: Your Value | D23: Implied EV at Peer Median Mult | F23: Implied Equity Value | G23: Per Share (₹)
A24: AURA FY2025E Revenue (₹cr) | B24: =PROJECTIONS!E21 -> 315.84
A25: AURA FY2025E EBITDA (₹cr) | B25: =PROJECTIONS!E25 -> 42.6384
A26: AURA FY2025E PAT (₹cr) | B26: =PROJECTIONS!E33 -> 28.63872
A27: Net Debt (₹cr) | B27: =ASSUMPTIONS!C26 -> -16 | C27: Derive from FY2024 Balance Sheet: Long-Term Debt (42) minus Cash & Equivalents (28) = 14 (pre-IPO). Post-IPO: Rs. 30 Cr of fresh issue proceeds repay debt, so Long-Term Debt falls to 12 and Net Debt = 12 − 28 = −16 (net cash). State clearly whether you are using pre-IPO or post-IPO net debt and justify your choice.
A28: Shares Outstanding (cr) | B28: 10
A29: AURA IMPLIED SHARE PRICE — Apply peer multiples to AURA projected financials
A30: Method | B30: Applied Multiple | C30: Implied EV (₹cr) | D30: (-) Net Debt (₹cr) | E30: Equity Value (₹cr) | F30: Shares (cr) | G30: Implied Price (₹/share) | H30: Notes / Approach
A31: EV / Revenue | B31: 5 | C31: =B24*B31 -> 1579.2 | D31: =B27 -> -16 | E31: =C31-D31 -> 1595.2 | F31: 10 | G31: =E31/F31 -> 159.52 | H31: EV = AURA Revenue × Applied Multiple. Equity Value = EV − Net Debt. Implied Price = Equity Value ÷ Shares Outstanding.
A32: EV / EBITDA | B32: 40 | C32: =B25*B32 -> 1705.536 | D32: =B27 -> -16 | E32: =C32-D32 -> 1721.536 | F32: 10 | G32: =E32/F32 -> 172.1536 | H32: EV = AURA EBITDA × Applied Multiple. Equity Value = EV − Net Debt. Implied Price = Equity Value ÷ Shares Outstanding.
A33: P / E | B33: 52 | C33: N/A | D33: N/A | E33: =B33*B26 -> 1489.2134 | F33: 10 | G33: =E33/F33 -> 148.92134 | H33: P/E method: Equity Value = AURA PAT × Applied Multiple. No EV bridge needed. Implied Price = Equity Value ÷ Shares Outstanding.
A37: ANALYST COMMENTARY — Premium or Discount to Peers?
A38: 1. Premium vs. Discount to Peers: AURA can command a moderate premium over traditional FMCG players due to its digital-first model and strong 60% gross margins. However, it should trade at a slight discount to large high-growth companies like Tata Consumer Products because of its smaller scale and early-stage profitability. 2. Justification of Multiples: EV/Revenue (5.0x): Reflects strong growth potential in the D2C wellness segment. EV/EBITDA (40.0x): Slightly conservative to account for execution risk and smaller scale. P/E (52.0x): Supports high earnings quality and strong cash flow generation. Based on the triangulation of our DCF (₹84.5) and our Relative Valuation (₹149 - ₹172), AURA is fundamentally undervalued at the anticipated IPO offer price of ₹66. The "Margin of Safety" is substantial, and we recommend a STRONG BUY as the stock is positioned for significant re-rating post-listing.
A44: CONFIDENTIAL | Project Lumina | FinOrbits IB Championship S1

Sheet SUMMARY
A1: VALUATION SUMMARY — PROJECT LUMINA | FINAL RECOMMENDATION
A6: SECTION 1 — VALUATION OUTPUT SUMMARY
A7: Methodology | B7: Low (₹/share) | C7: Base Case (₹/share) | D7: High (₹/share) | E7: Weight % | F7: Weighted Value
A8: DCF Valuation | B8: ='DCF VALUATION'!B51 -> 76.028574 | C8: ='DCF VALUATION'!B50 -> 84.476193 | D8: ='DCF VALUATION'!B52 -> 92.923812 | E8: 0.4 | F8: =C8*E8 -> 33.790477 | G8: Link from DCF tab, Section 4
A9: EV/EBITDA Comps | B9: =COMPARABLES!G32*0.9 -> 154.93824 | C9: =COMPARABLES!G32 -> 172.1536 | D9: =COMPARABLES!G32*1.1 -> 189.36896 | E9: 0.4 | F9: =C9*E9 -> 68.86144 | G9: From Comparables — EBITDA-based
A10: P/E Comps | B10: =COMPARABLES!G33*0.9 -> 134.02921 | C10: =COMPARABLES!G33 -> 148.92134 | D10: =COMPARABLES!G33*1.1 -> 163.81348 | E10: 0.2 | F10: =C10*E10 -> 29.784269 | G10: From Comparables — P/E based
A11: WEIGHTED AVERAGE | B11: =SUMPRODUCT(B8:B10,E8:E10) -> 119.19257 | C11: =SUMPRODUCT(C8:C10,E8:E10) -> 132.43619 | D11: {=SUMPRODUCT(D8:D10*E8:E10)} -> 145.6798 | E11: 1 | F11: =SUM(F8:F10) -> 132.43619 | G11: = Sum of (Base x Weight) each method
A14: SECTION 2 — FINAL RECOMMENDATION
A15: IPO Price Band Recommendation (₹/share) | B15: Low: 119 | High: 146
A16: Recommendation | B16: SUBSCRIBE
A17: Upside / Downside to Mid-Band | B17: 28% upside basedon DCF / Negligible downside because of strong Floor
A18: Primary Valuation Method Used | B18: 50% DCF / 50% EV/EBITDA / Blended , we use DCF for long term intrinsic value and EV/EBITDA to capture the current market premium
A19: Key Assumption Driving Valuation | B19: Sustainable EBITDA margin expansion & Revenue CAGR of 19%+
A20: One Key Risk to Your Thesis | B20: Execution Risk in highly competitive D2C wellness space + inventory days inconsistency (balance sheet 90d vs stated 50d)
A23: SECTION 3 — FOOTBALL FIELD CHART
A24: INSERT YOUR FOOTBALL FIELD CHART HERE How to build it: 1. Create a horizontal bar chart (Insert > Bar Chart > Stacked Bar) 2. X-axis = Share price in ₹. Y-axis = 3 methodologies (DCF, EV/EBITDA, P/E) 3. Each bar shows the range from Low to High for that methodology 4. Add a vertical line or separate series for your recommended price band 5. Color: #4AACFF (blue) for your recommended band. Grey for others. This is the visual centerpiece of your submission deck.
A34: CONFIDENTIAL | Project Lumina | FinOrbits IB Championship S1 | finorbits.com
A37: SECTION 3 — FOOTBALL FIELD CHART
B39: LOW | C39: HIGH
A40: DCF | B40: 76.028574 | C40: 84.476193
A41: EV/EBITDA | B41: 154.93824 | C41: 172.1536
A42: P/E | B42: 134.02921 | C42: 148.92134
